<?xml version="1.0"?>
<robot name="MotionDevice">

  <link name="base_link">
    <inertial>
      <mass value="0.0001"/>
      <origin xyz="0.0 0.0 0.0"/>
      <inertia ixx="1e-10" ixy="0." ixz="0." iyy="1e-10" iyz="0." izz="1e-10"/>
    </inertial>

    <visual>
      <origin rpy="0 0 0" xyz="0 0 0"/>
      <geometry>
        <sphere radius="0.02"/>
      </geometry>
      <material name="red">
        <color rgba="1 0 0 1"/>
      </material>
    </visual>

  </link>

  <link name="x_link">
    <inertial>
      <mass value="0.0001"/>
      <origin xyz="0.0 0.0 0.0"/>
      <inertia ixx="1e-10" ixy="0." ixz="0." iyy="1e-10" iyz="0." izz="1e-10"/>
    </inertial>
  </link>

  <link name="y_link">
    <inertial>
      <mass value="0.0001"/>
      <origin xyz="0.0 0.0 0.0"/>
      <inertia ixx="1e-10" ixy="0." ixz="0." iyy="1e-10" iyz="0." izz="1e-10"/>
    </inertial>
  </link>

  <link name="z_link">
    <inertial>
      <mass value="0.0001"/>
      <origin xyz="0.0 0.0 0.0"/>
      <inertia ixx="1e-10" ixy="0." ixz="0." iyy="1e-10" iyz="0." izz="1e-10"/>
    </inertial>
  </link>

  <link name="rot_x_link">
    <inertial>
      <mass value="0.0001"/>
      <origin xyz="0.0 0.0 0.0"/>
      <inertia ixx="1e-10" ixy="0." ixz="0." iyy="1e-10" iyz="0." izz="1e-10"/>
    </inertial>
  </link>

  <link name="rot_y_link">
    <inertial>
      <mass value="0.0001"/>
      <origin xyz="0.0 0.0 0.0"/>
      <inertia ixx="1e-10" ixy="0." ixz="0." iyy="1e-10" iyz="0." izz="1e-10"/>
    </inertial>
  </link>

  <link name="rot_z_link">
    <inertial>
      <mass value="0.0001"/>
      <origin xyz="0.0 0.0 0.0"/>
      <inertia ixx="1e-10" ixy="0." ixz="0." iyy="1e-10" iyz="0." izz="1e-10"/>
    </inertial>
    <visual>
      <origin rpy="0 0 0" xyz="0 0 0"/>
      <geometry>
        <sphere radius="0.02"/>
      </geometry>
      <material name="green">
        <color rgba="0 1 0 1"/>
      </material>
    </visual>
  </link>

  <!-- active joints for moving the end-effector -->

  <joint name="axis_x" type="prismatic">
    <axis xyz="1 0 0"/>
    <origin rpy="0 0 0" xyz="0 0 0"/>
    <parent link="base_link"/>
    <child link="x_link"/>
    <limit lower="-100" upper="100"/>
    <joint_properties damping=".0" friction=".0"/>
    <limit effort="100" velocity="100"/>
  </joint>

  <joint name="axis_y" type="prismatic">
    <axis xyz="0 1 0"/>
    <origin rpy="0 0 0" xyz="0 0 0"/>
    <parent link="x_link"/>
    <child link="y_link"/>
    <limit lower="-100" upper="100"/>
    <joint_properties damping=".0" friction=".0"/>
    <limit effort="100" velocity="100"/>
  </joint>

  <joint name="axis_z" type="prismatic">
    <axis xyz="0 0 1"/>
    <origin rpy="0 0 0" xyz="0 0 0"/>
    <parent link="y_link"/>
    <child link="z_link"/>
    <limit lower="-100" upper="100"/>
    <joint_properties damping=".0" friction=".0"/>
    <limit effort="100" velocity="100"/>
  </joint>

  <joint name="hinge_x" type="continuous">
    <axis xyz="1 0 0"/>
    <origin rpy="0 0 0" xyz="0 0 0"/>
    <parent link="z_link"/>
    <child link="rot_x_link"/>
    <joint_properties damping=".0" friction=".0"/>
  </joint>

  <joint name="hinge_y" type="continuous">
    <axis xyz="0 1 0"/>
    <origin rpy="0 0 0" xyz="0 0 0"/>
    <parent link="rot_x_link"/>
    <child link="rot_y_link"/>
    <joint_properties damping=".0" friction=".0"/>
  </joint>

  <joint name="hinge_z" type="continuous">
    <axis xyz="0 0 1"/>
    <origin rpy="0 0 0" xyz="0 0 0"/>
    <parent link="rot_y_link"/>
    <child link="rot_z_link"/>
    <joint_properties damping=".0" friction=".0"/>
  </joint>

</robot>
